Watching for file changes with StatReloader
"GET /admin/auth/user/ HTTP/1.1" 200 15376
"GET /admin/jsi18n/ HTTP/1.1" 200 3342
- Broken pipe from ('127.0.0.1', 55934)
"GET /static/admin/img/search.svg HTTP/1.1" 200 458
"GET /static/admin/img/icon-no.svg HTTP/1.1" 200 560
"GET /static/admin/img/icon-yes.svg HTTP/1.1" 200 436
"GET /static/admin/img/sorting-icons.svg HTTP/1.1" 200 1097
Not Found: /
"GET / HTTP/1.1" 404 4038
"GET /home/ HTTP/1.1" 200 6874
Watching for file changes with StatReloader
C:\django\insurance_company\insurance_company_app\models\insurance_client.py changed, reloading.
Watching for file changes with StatReloader
C:\django\insurance_company\insurance_company_app\models\insurance_client.py changed, reloading.
Watching for file changes with StatReloader
C:\django\insurance_company\insurance_company_app\models\insurance_client.py changed, reloading.
Watching for file changes with StatReloader
C:\django\insurance_company\insurance_company_app\models\insurance_client.py changed, reloading.
Watching for file changes with StatReloader
C:\django\insurance_company\insurance_company_app\models\insurance_client.py changed, reloading.
Watching for file changes with StatReloader
C:\django\insurance_company\insurance_company_app\models\insurance_client.py changed, reloading.
Watching for file changes with StatReloader
C:\django\insurance_company\insurance_company_app\models\insurance_client.py changed, reloading.
Watching for file changes with StatReloader
C:\django\insurance_company\insurance_company_app\models\insurance_client.py changed, reloading.
Watching for file changes with StatReloader
C:\django\insurance_company\insurance_company_app\models\insurance_client.py changed, reloading.
Watching for file changes with StatReloader
C:\django\insurance_company\insurance_company_app\models\insurance_client.py changed, reloading.
Watching for file changes with StatReloader
Watching for file changes with StatReloader
Watching for file changes with StatReloader
Not Found: /
"GET / HTTP/1.1" 404 4038
Internal Server Error: /home/
Traceback (most recent call last):
  File "C:\django\.venv\Lib\site-packages\urllib3\connection.py", line 198, in _new_conn
    sock = connection.create_connection(
           ^^^^^^^^^^^^^^^^^^^^^^^^^^^^^
  File "C:\django\.venv\Lib\site-packages\urllib3\util\connection.py", line 60, in create_connection
    for res in socket.getaddrinfo(host, port, family, socket.SOCK_STREAM):
               ^^^^^^^^^^^^^^^^^^^^^^^^^^^^^^^^^^^^^^^^^^^^^^^^^^^^^^^^^^
  File "C:\Program Files\WindowsApps\PythonSoftwareFoundation.Python.3.12_3.12.1008.0_x64__qbz5n2kfra8p0\Lib\socket.py", line 963, in getaddrinfo
    for res in _socket.getaddrinfo(host, port, family, type, proto, flags):
               ^^^^^^^^^^^^^^^^^^^^^^^^^^^^^^^^^^^^^^^^^^^^^^^^^^^^^^^^^^^
socket.gaierror: [Errno 11001] getaddrinfo failed

The above exception was the direct cause of the following exception:

Traceback (most recent call last):
  File "C:\django\.venv\Lib\site-packages\urllib3\connectionpool.py", line 793, in urlopen
    response = self._make_request(
               ^^^^^^^^^^^^^^^^^^^
  File "C:\django\.venv\Lib\site-packages\urllib3\connectionpool.py", line 491, in _make_request
    raise new_e
  File "C:\django\.venv\Lib\site-packages\urllib3\connectionpool.py", line 467, in _make_request
    self._validate_conn(conn)
  File "C:\django\.venv\Lib\site-packages\urllib3\connectionpool.py", line 1099, in _validate_conn
    conn.connect()
  File "C:\django\.venv\Lib\site-packages\urllib3\connection.py", line 616, in connect
    self.sock = sock = self._new_conn()
                       ^^^^^^^^^^^^^^^^
  File "C:\django\.venv\Lib\site-packages\urllib3\connection.py", line 205, in _new_conn
    raise NameResolutionError(self.host, self, e) from e
urllib3.exceptions.NameResolutionError: <urllib3.connection.HTTPSConnection object at 0x000002026173DB20>: Failed to resolve 'official-joke-api.appspot.com' ([Errno 11001] getaddrinfo failed)

The above exception was the direct cause of the following exception:

Traceback (most recent call last):
  File "C:\django\.venv\Lib\site-packages\requests\adapters.py", line 486, in send
    resp = conn.urlopen(
           ^^^^^^^^^^^^^
  File "C:\django\.venv\Lib\site-packages\urllib3\connectionpool.py", line 847, in urlopen
    retries = retries.increment(
              ^^^^^^^^^^^^^^^^^^
  File "C:\django\.venv\Lib\site-packages\urllib3\util\retry.py", line 515, in increment
    raise MaxRetryError(_pool, url, reason) from reason  # type: ignore[arg-type]
    ^^^^^^^^^^^^^^^^^^^^^^^^^^^^^^^^^^^^^^^^^^^^^^^^^^^
urllib3.exceptions.MaxRetryError: HTTPSConnectionPool(host='official-joke-api.appspot.com', port=443): Max retries exceeded with url: /random_joke (Caused by NameResolutionError("<urllib3.connection.HTTPSConnection object at 0x000002026173DB20>: Failed to resolve 'official-joke-api.appspot.com' ([Errno 11001] getaddrinfo failed)"))

During handling of the above exception, another exception occurred:

Traceback (most recent call last):
  File "C:\django\.venv\Lib\site-packages\django\core\handlers\exception.py", line 55, in inner
    response = get_response(request)
               ^^^^^^^^^^^^^^^^^^^^^
  File "C:\django\.venv\Lib\site-packages\django\core\handlers\base.py", line 197, in _get_response
    response = wrapped_callback(request, *callback_args, **callback_kwargs)
               ^^^^^^^^^^^^^^^^^^^^^^^^^^^^^^^^^^^^^^^^^^^^^^^^^^^^^^^^^^^^
  File "C:\django\insurance_company\insurance_company_app\views\news.py", line 6, in news_view
    funny_joke = random_joke.RandomJokeService.get_random_joke()
                 ^^^^^^^^^^^^^^^^^^^^^^^^^^^^^^^^^^^^^^^^^^^^^^^
  File "C:\django\insurance_company\insurance_company_app\services\random_joke.py", line 7, in get_random_joke
    return requests.get('https://official-joke-api.appspot.com/random_joke').json()
           ^^^^^^^^^^^^^^^^^^^^^^^^^^^^^^^^^^^^^^^^^^^^^^^^^^^^^^^^^^^^^^^^^
  File "C:\django\.venv\Lib\site-packages\requests\api.py", line 73, in get
    return request("get", url, params=params, **kwargs)
           ^^^^^^^^^^^^^^^^^^^^^^^^^^^^^^^^^^^^^^^^^^^^
  File "C:\django\.venv\Lib\site-packages\requests\api.py", line 59, in request
    return session.request(method=method, url=url, **kwargs)
           ^^^^^^^^^^^^^^^^^^^^^^^^^^^^^^^^^^^^^^^^^^^^^^^^^
  File "C:\django\.venv\Lib\site-packages\requests\sessions.py", line 589, in request
    resp = self.send(prep, **send_kwargs)
           ^^^^^^^^^^^^^^^^^^^^^^^^^^^^^^
  File "C:\django\.venv\Lib\site-packages\requests\sessions.py", line 703, in send
    r = adapter.send(request, **kwargs)
        ^^^^^^^^^^^^^^^^^^^^^^^^^^^^^^^
  File "C:\django\.venv\Lib\site-packages\requests\adapters.py", line 519, in send
    raise ConnectionError(e, request=request)
requests.exceptions.ConnectionError: HTTPSConnectionPool(host='official-joke-api.appspot.com', port=443): Max retries exceeded with url: /random_joke (Caused by NameResolutionError("<urllib3.connection.HTTPSConnection object at 0x000002026173DB20>: Failed to resolve 'official-joke-api.appspot.com' ([Errno 11001] getaddrinfo failed)"))
"GET /home/ HTTP/1.1" 500 164729
"GET /home/ HTTP/1.1" 200 6849
C:\django\insurance_company\insurance_company_app\middleware\current_datetime_info.py changed, reloading.
Watching for file changes with StatReloader
Watching for file changes with StatReloader
Internal Server Error: /home/
Traceback (most recent call last):
  File "C:\django\.venv\Lib\site-packages\django\core\handlers\exception.py", line 55, in inner
    response = get_response(request)
               ^^^^^^^^^^^^^^^^^^^^^
  File "C:\django\insurance_company\insurance_company_app\middleware\current_datetime_info.py", line 11, in __call__
    current_datetime = dateformat.format(timezone.localtime(timezone.now()))
                       ^^^^^^^^^^^^^^^^^^^^^^^^^^^^^^^^^^^^^^^^^^^^^^^^^^^^^
TypeError: format() missing 1 required positional argument: 'format_string'
"GET /home/ HTTP/1.1" 500 62414
C:\django\insurance_company\insurance_company_app\middleware\current_datetime_info.py changed, reloading.
Watching for file changes with StatReloader
Internal Server Error: /home/
Traceback (most recent call last):
  File "C:\django\.venv\Lib\site-packages\django\core\handlers\exception.py", line 55, in inner
    response = get_response(request)
               ^^^^^^^^^^^^^^^^^^^^^
  File "C:\django\insurance_company\insurance_company_app\middleware\current_datetime_info.py", line 14, in __call__
    .formatmonth(current_datetime.year, current_datetime.month)
                 ^^^^^^^^^^^^^^^^^^^^^
AttributeError: 'str' object has no attribute 'year'
"GET /home/ HTTP/1.1" 500 62783
C:\django\insurance_company\insurance_company_app\middleware\current_datetime_info.py changed, reloading.
Watching for file changes with StatReloader
"GET /home/ HTTP/1.1" 200 6900
C:\django\insurance_company\insurance_company_app\middleware\current_datetime_info.py changed, reloading.
Watching for file changes with StatReloader
"GET /home/ HTTP/1.1" 200 6862
"GET /information/ HTTP/1.1" 200 156
Internal Server Error: /information/
Traceback (most recent call last):
  File "C:\django\.venv\Lib\site-packages\django\template\backends\django.py", line 61, in render
    return self.template.render(context)
           ^^^^^^^^^^^^^^^^^^^^^^^^^^^^^
  File "C:\django\.venv\Lib\site-packages\django\template\base.py", line 171, in render
    return self._render(context)
           ^^^^^^^^^^^^^^^^^^^^^
  File "C:\django\.venv\Lib\site-packages\django\template\base.py", line 163, in _render
    return self.nodelist.render(context)
           ^^^^^^^^^^^^^^^^^^^^^^^^^^^^^
  File "C:\django\.venv\Lib\site-packages\django\template\base.py", line 1000, in render
    return SafeString("".join([node.render_annotated(context) for node in self]))
                               ^^^^^^^^^^^^^^^^^^^^^^^^^^^^^^
  File "C:\django\.venv\Lib\site-packages\django\template\base.py", line 961, in render_annotated
    return self.render(context)
           ^^^^^^^^^^^^^^^^^^^^
  File "C:\django\.venv\Lib\site-packages\django\template\loader_tags.py", line 134, in render
    compiled_parent = self.get_parent(context)
                      ^^^^^^^^^^^^^^^^^^^^^^^^
  File "C:\django\.venv\Lib\site-packages\django\template\loader_tags.py", line 131, in get_parent
    return self.find_template(parent, context)
           ^^^^^^^^^^^^^^^^^^^^^^^^^^^^^^^^^^^
  File "C:\django\.venv\Lib\site-packages\django\template\loader_tags.py", line 109, in find_template
    template, origin = context.template.engine.find_template(
                       ^^^^^^^^^^^^^^^^^^^^^^^^^^^^^^^^^^^^^^
  File "C:\django\.venv\Lib\site-packages\django\template\engine.py", line 163, in find_template
    raise TemplateDoesNotExist(name, tried=tried)
django.template.exceptions.TemplateDoesNotExist: layout.html

The above exception was the direct cause of the following exception:

Traceback (most recent call last):
  File "C:\django\.venv\Lib\site-packages\django\core\handlers\exception.py", line 55, in inner
    response = get_response(request)
               ^^^^^^^^^^^^^^^^^^^^^
  File "C:\django\.venv\Lib\site-packages\django\core\handlers\base.py", line 197, in _get_response
    response = wrapped_callback(request, *callback_args, **callback_kwargs)
               ^^^^^^^^^^^^^^^^^^^^^^^^^^^^^^^^^^^^^^^^^^^^^^^^^^^^^^^^^^^^
  File "C:\django\.venv\Lib\site-packages\django\contrib\auth\decorators.py", line 23, in _wrapper_view
    return view_func(request, *args, **kwargs)
           ^^^^^^^^^^^^^^^^^^^^^^^^^^^^^^^^^^^
  File "C:\django\.venv\Lib\site-packages\django\contrib\auth\decorators.py", line 23, in _wrapper_view
    return view_func(request, *args, **kwargs)
           ^^^^^^^^^^^^^^^^^^^^^^^^^^^^^^^^^^^
  File "C:\django\insurance_company\insurance_company_app\views\accounts.py", line 45, in superuser_extra_view
    return render(request, 'common/superuser_statistics.html', data)
           ^^^^^^^^^^^^^^^^^^^^^^^^^^^^^^^^^^^^^^^^^^^^^^^^^^^^^^^^^
  File "C:\django\.venv\Lib\site-packages\django\shortcuts.py", line 25, in render
    content = loader.render_to_string(template_name, context, request, using=using)
              ^^^^^^^^^^^^^^^^^^^^^^^^^^^^^^^^^^^^^^^^^^^^^^^^^^^^^^^^^^^^^^^^^^^^^
  File "C:\django\.venv\Lib\site-packages\django\template\loader.py", line 62, in render_to_string
    return template.render(context, request)
           ^^^^^^^^^^^^^^^^^^^^^^^^^^^^^^^^^
  File "C:\django\.venv\Lib\site-packages\django\template\backends\django.py", line 63, in render
    reraise(exc, self.backend)
  File "C:\django\.venv\Lib\site-packages\django\template\backends\django.py", line 84, in reraise
    raise new from exc
django.template.exceptions.TemplateDoesNotExist: layout.html
"GET /information/ HTTP/1.1" 500 134777
C:\django\insurance_company\insurance_company_app\views\accounts.py changed, reloading.
Watching for file changes with StatReloader
Internal Server Error: /information/
Traceback (most recent call last):
  File "C:\django\.venv\Lib\site-packages\django\core\handlers\exception.py", line 55, in inner
    response = get_response(request)
               ^^^^^^^^^^^^^^^^^^^^^
  File "C:\django\.venv\Lib\site-packages\django\core\handlers\base.py", line 197, in _get_response
    response = wrapped_callback(request, *callback_args, **callback_kwargs)
               ^^^^^^^^^^^^^^^^^^^^^^^^^^^^^^^^^^^^^^^^^^^^^^^^^^^^^^^^^^^^
  File "C:\django\.venv\Lib\site-packages\django\contrib\auth\decorators.py", line 23, in _wrapper_view
    return view_func(request, *args, **kwargs)
           ^^^^^^^^^^^^^^^^^^^^^^^^^^^^^^^^^^^
  File "C:\django\.venv\Lib\site-packages\django\contrib\auth\decorators.py", line 23, in _wrapper_view
    return view_func(request, *args, **kwargs)
           ^^^^^^^^^^^^^^^^^^^^^^^^^^^^^^^^^^^
  File "C:\django\insurance_company\insurance_company_app\views\accounts.py", line 44, in superuser_extra_view
    'sales_statistics': statistics.get_sales_statistics()
                        ^^^^^^^^^^^^^^^^^^^^^^^^^^^^^^^
AttributeError: 'function' object has no attribute 'get_sales_statistics'
"GET /information/ HTTP/1.1" 500 76840
C:\django\insurance_company\insurance_company_app\views\accounts.py changed, reloading.
Watching for file changes with StatReloader
"GET /information/ HTTP/1.1" 200 228
"GET /information/ HTTP/1.1" 200 377
C:\django\insurance_company\insurance_company_app\views\accounts.py changed, reloading.
Watching for file changes with StatReloader
"GET /information/ HTTP/1.1" 200 592
C:\django\insurance_company\insurance_company_app\views\accounts.py changed, reloading.
Watching for file changes with StatReloader
C:\django\insurance_company\insurance_company_app\views\accounts.py changed, reloading.
Watching for file changes with StatReloader
Internal Server Error: /information/
Traceback (most recent call last):
  File "C:\django\.venv\Lib\site-packages\django\db\models\sql\query.py", line 1890, in transform
    return self.try_transform(wrapped, name)
           ^^^^^^^^^^^^^^^^^^^^^^^^^^^^^^^^^
  File "C:\django\.venv\Lib\site-packages\django\db\models\sql\query.py", line 1427, in try_transform
    raise FieldError(
django.core.exceptions.FieldError: Unsupported lookup 'name' for TextField or join on the field not permitted.

During handling of the above exception, another exception occurred:

Traceback (most recent call last):
  File "C:\django\.venv\Lib\site-packages\django\core\handlers\exception.py", line 55, in inner
    response = get_response(request)
               ^^^^^^^^^^^^^^^^^^^^^
  File "C:\django\.venv\Lib\site-packages\django\core\handlers\base.py", line 197, in _get_response
    response = wrapped_callback(request, *callback_args, **callback_kwargs)
               ^^^^^^^^^^^^^^^^^^^^^^^^^^^^^^^^^^^^^^^^^^^^^^^^^^^^^^^^^^^^
  File "C:\django\.venv\Lib\site-packages\django\contrib\auth\decorators.py", line 23, in _wrapper_view
    return view_func(request, *args, **kwargs)
           ^^^^^^^^^^^^^^^^^^^^^^^^^^^^^^^^^^^
  File "C:\django\.venv\Lib\site-packages\django\contrib\auth\decorators.py", line 23, in _wrapper_view
    return view_func(request, *args, **kwargs)
           ^^^^^^^^^^^^^^^^^^^^^^^^^^^^^^^^^^^
  File "C:\django\insurance_company\insurance_company_app\views\accounts.py", line 46, in superuser_extra_view
    'most_popular_insurance': get_most_popular_insurance_type(),
                              ^^^^^^^^^^^^^^^^^^^^^^^^^^^^^^^^^
  File "C:\django\insurance_company\insurance_company_app\views\statistics.py", line 49, in get_most_popular_insurance_type
    most_popular_type = InsuranceContract.objects.values('insurance_type__name').annotate(
                        ^^^^^^^^^^^^^^^^^^^^^^^^^^^^^^^^^^^^^^^^^^^^^^^^^^^^^^^^
  File "C:\django\.venv\Lib\site-packages\django\db\models\manager.py", line 87, in manager_method
    return getattr(self.get_queryset(), name)(*args, **kwargs)
           ^^^^^^^^^^^^^^^^^^^^^^^^^^^^^^^^^^^^^^^^^^^^^^^^^^^
  File "C:\django\.venv\Lib\site-packages\django\db\models\query.py", line 1360, in values
    clone = self._values(*fields, **expressions)
            ^^^^^^^^^^^^^^^^^^^^^^^^^^^^^^^^^^^^
  File "C:\django\.venv\Lib\site-packages\django\db\models\query.py", line 1355, in _values
    clone.query.set_values(fields)
  File "C:\django\.venv\Lib\site-packages\django\db\models\sql\query.py", line 2502, in set_values
    self.add_fields(field_names, True)
  File "C:\django\.venv\Lib\site-packages\django\db\models\sql\query.py", line 2208, in add_fields
    cols.append(join_info.transform_function(target, final_alias))
                ^^^^^^^^^^^^^^^^^^^^^^^^^^^^^^^^^^^^^^^^^^^^^^^^^
  File "C:\django\.venv\Lib\site-packages\django\db\models\sql\query.py", line 1894, in transform
    raise last_field_exception
  File "C:\django\.venv\Lib\site-packages\django\db\models\sql\query.py", line 1867, in setup_joins
    path, final_field, targets, rest = self.names_to_path(
                                       ^^^^^^^^^^^^^^^^^^^
  File "C:\django\.venv\Lib\site-packages\django\db\models\sql\query.py", line 1809, in names_to_path
    raise FieldError(
django.core.exceptions.FieldError: Cannot resolve keyword 'name' into field. Join on 'insurance_type' not permitted.
"GET /information/ HTTP/1.1" 500 133196
C:\django\insurance_company\insurance_company_app\views\statistics.py changed, reloading.
Watching for file changes with StatReloader
Internal Server Error: /information/
Traceback (most recent call last):
  File "C:\django\.venv\Lib\site-packages\django\core\handlers\exception.py", line 55, in inner
    response = get_response(request)
               ^^^^^^^^^^^^^^^^^^^^^
  File "C:\django\.venv\Lib\site-packages\django\core\handlers\base.py", line 197, in _get_response
    response = wrapped_callback(request, *callback_args, **callback_kwargs)
               ^^^^^^^^^^^^^^^^^^^^^^^^^^^^^^^^^^^^^^^^^^^^^^^^^^^^^^^^^^^^
  File "C:\django\.venv\Lib\site-packages\django\contrib\auth\decorators.py", line 23, in _wrapper_view
    return view_func(request, *args, **kwargs)
           ^^^^^^^^^^^^^^^^^^^^^^^^^^^^^^^^^^^
  File "C:\django\.venv\Lib\site-packages\django\contrib\auth\decorators.py", line 23, in _wrapper_view
    return view_func(request, *args, **kwargs)
           ^^^^^^^^^^^^^^^^^^^^^^^^^^^^^^^^^^^
  File "C:\django\insurance_company\insurance_company_app\views\accounts.py", line 46, in superuser_extra_view
    'most_popular_insurance': get_most_popular_insurance_type(),
                              ^^^^^^^^^^^^^^^^^^^^^^^^^^^^^^^^^
  File "C:\django\insurance_company\insurance_company_app\views\statistics.py", line 52, in get_most_popular_insurance_type
    return most_popular_type
           ^^^^^^^^^^^^^^^^^
NameError: name 'most_popular_type' is not defined
"GET /information/ HTTP/1.1" 500 80194
C:\django\insurance_company\insurance_company_app\views\statistics.py changed, reloading.
Watching for file changes with StatReloader
Internal Server Error: /information/
Traceback (most recent call last):
  File "C:\django\.venv\Lib\site-packages\django\core\handlers\exception.py", line 55, in inner
    response = get_response(request)
               ^^^^^^^^^^^^^^^^^^^^^
  File "C:\django\.venv\Lib\site-packages\django\core\handlers\base.py", line 197, in _get_response
    response = wrapped_callback(request, *callback_args, **callback_kwargs)
               ^^^^^^^^^^^^^^^^^^^^^^^^^^^^^^^^^^^^^^^^^^^^^^^^^^^^^^^^^^^^
  File "C:\django\.venv\Lib\site-packages\django\contrib\auth\decorators.py", line 23, in _wrapper_view
    return view_func(request, *args, **kwargs)
           ^^^^^^^^^^^^^^^^^^^^^^^^^^^^^^^^^^^
  File "C:\django\.venv\Lib\site-packages\django\contrib\auth\decorators.py", line 23, in _wrapper_view
    return view_func(request, *args, **kwargs)
           ^^^^^^^^^^^^^^^^^^^^^^^^^^^^^^^^^^^
  File "C:\django\insurance_company\insurance_company_app\views\accounts.py", line 47, in superuser_extra_view
    'clients_age': get_clients_age_statistics(),
                   ^^^^^^^^^^^^^^^^^^^^^^^^^^^^
  File "C:\django\insurance_company\insurance_company_app\views\statistics.py", line 43, in get_clients_age_statistics
    median_age=statistics.median('age')
               ^^^^^^^^^^^^^^^^^
AttributeError: 'function' object has no attribute 'median'
"GET /information/ HTTP/1.1" 500 80005
C:\django\insurance_company\insurance_company_app\views\statistics.py changed, reloading.
Watching for file changes with StatReloader
C:\django\insurance_company\insurance_company_app\views\statistics.py changed, reloading.
Watching for file changes with StatReloader
C:\django\insurance_company\insurance_company_app\views\statistics.py changed, reloading.
Watching for file changes with StatReloader
C:\django\insurance_company\insurance_company_app\views\statistics.py changed, reloading.
Watching for file changes with StatReloader
C:\django\insurance_company\insurance_company_app\views\statistics.py changed, reloading.
Watching for file changes with StatReloader
C:\django\insurance_company\insurance_company_app\views\statistics.py changed, reloading.
Watching for file changes with StatReloader
C:\django\insurance_company\insurance_company_app\views\statistics.py changed, reloading.
Watching for file changes with StatReloader
C:\django\insurance_company\insurance_company_app\views\statistics.py changed, reloading.
Watching for file changes with StatReloader
Internal Server Error: /information/
Traceback (most recent call last):
  File "C:\django\.venv\Lib\site-packages\django\core\handlers\exception.py", line 55, in inner
    response = get_response(request)
               ^^^^^^^^^^^^^^^^^^^^^
  File "C:\django\.venv\Lib\site-packages\django\core\handlers\base.py", line 197, in _get_response
    response = wrapped_callback(request, *callback_args, **callback_kwargs)
               ^^^^^^^^^^^^^^^^^^^^^^^^^^^^^^^^^^^^^^^^^^^^^^^^^^^^^^^^^^^^
  File "C:\django\.venv\Lib\site-packages\django\contrib\auth\decorators.py", line 23, in _wrapper_view
    return view_func(request, *args, **kwargs)
           ^^^^^^^^^^^^^^^^^^^^^^^^^^^^^^^^^^^
  File "C:\django\.venv\Lib\site-packages\django\contrib\auth\decorators.py", line 23, in _wrapper_view
    return view_func(request, *args, **kwargs)
           ^^^^^^^^^^^^^^^^^^^^^^^^^^^^^^^^^^^
  File "C:\django\insurance_company\insurance_company_app\views\accounts.py", line 47, in superuser_extra_view
    'clients_age': get_clients_age_statistics(),
                   ^^^^^^^^^^^^^^^^^^^^^^^^^^^^
  File "C:\django\insurance_company\insurance_company_app\views\statistics.py", line 42, in get_clients_age_statistics
    median_age = median(all_ages)
                 ^^^^^^^^^^^^^^^^
  File "C:\Program Files\WindowsApps\PythonSoftwareFoundation.Python.3.12_3.12.1008.0_x64__qbz5n2kfra8p0\Lib\statistics.py", line 617, in median
    raise StatisticsError("no median for empty data")
statistics.StatisticsError: no median for empty data
"GET /information/ HTTP/1.1" 500 84202
Not Found: /favicon.ico
- Broken pipe from ('127.0.0.1', 50788)
C:\django\insurance_company\insurance_company_app\views\statistics.py changed, reloading.
Watching for file changes with StatReloader
Internal Server Error: /information/
Traceback (most recent call last):
  File "C:\django\.venv\Lib\site-packages\django\core\handlers\exception.py", line 55, in inner
    response = get_response(request)
               ^^^^^^^^^^^^^^^^^^^^^
  File "C:\django\.venv\Lib\site-packages\django\core\handlers\base.py", line 197, in _get_response
    response = wrapped_callback(request, *callback_args, **callback_kwargs)
               ^^^^^^^^^^^^^^^^^^^^^^^^^^^^^^^^^^^^^^^^^^^^^^^^^^^^^^^^^^^^
  File "C:\django\.venv\Lib\site-packages\django\contrib\auth\decorators.py", line 23, in _wrapper_view
    return view_func(request, *args, **kwargs)
           ^^^^^^^^^^^^^^^^^^^^^^^^^^^^^^^^^^^
  File "C:\django\.venv\Lib\site-packages\django\contrib\auth\decorators.py", line 23, in _wrapper_view
    return view_func(request, *args, **kwargs)
           ^^^^^^^^^^^^^^^^^^^^^^^^^^^^^^^^^^^
  File "C:\django\insurance_company\insurance_company_app\views\accounts.py", line 47, in superuser_extra_view
    'clients_age': get_clients_age_statistics(),
                   ^^^^^^^^^^^^^^^^^^^^^^^^^^^^
  File "C:\django\insurance_company\insurance_company_app\views\statistics.py", line 42, in get_clients_age_statistics
    median_age = statistics.median(all_ages)
                 ^^^^^^^^^^^^^^^^^
AttributeError: 'function' object has no attribute 'median'
"GET /information/ HTTP/1.1" 500 80644
C:\django\insurance_company\insurance_company_app\views\statistics.py changed, reloading.
Watching for file changes with StatReloader
Internal Server Error: /information/
Traceback (most recent call last):
  File "C:\django\.venv\Lib\site-packages\django\core\handlers\exception.py", line 55, in inner
    response = get_response(request)
               ^^^^^^^^^^^^^^^^^^^^^
  File "C:\django\.venv\Lib\site-packages\django\core\handlers\base.py", line 197, in _get_response
    response = wrapped_callback(request, *callback_args, **callback_kwargs)
               ^^^^^^^^^^^^^^^^^^^^^^^^^^^^^^^^^^^^^^^^^^^^^^^^^^^^^^^^^^^^
  File "C:\django\.venv\Lib\site-packages\django\contrib\auth\decorators.py", line 23, in _wrapper_view
    return view_func(request, *args, **kwargs)
           ^^^^^^^^^^^^^^^^^^^^^^^^^^^^^^^^^^^
  File "C:\django\.venv\Lib\site-packages\django\contrib\auth\decorators.py", line 23, in _wrapper_view
    return view_func(request, *args, **kwargs)
           ^^^^^^^^^^^^^^^^^^^^^^^^^^^^^^^^^^^
  File "C:\django\insurance_company\insurance_company_app\views\accounts.py", line 47, in superuser_extra_view
    'clients_age': get_clients_age_statistics(),
                   ^^^^^^^^^^^^^^^^^^^^^^^^^^^^
  File "C:\django\insurance_company\insurance_company_app\views\statistics.py", line 42, in get_clients_age_statistics
    median_age = median(all_ages)
                 ^^^^^^^^^^^^^^^^
  File "C:\Program Files\WindowsApps\PythonSoftwareFoundation.Python.3.12_3.12.1008.0_x64__qbz5n2kfra8p0\Lib\statistics.py", line 617, in median
    raise StatisticsError("no median for empty data")
statistics.StatisticsError: no median for empty data
"GET /information/ HTTP/1.1" 500 84202
C:\django\insurance_company\insurance_company_app\views\statistics.py changed, reloading.
Watching for file changes with StatReloader
Internal Server Error: /information/
Traceback (most recent call last):
  File "C:\django\.venv\Lib\site-packages\django\core\handlers\exception.py", line 55, in inner
    response = get_response(request)
               ^^^^^^^^^^^^^^^^^^^^^
  File "C:\django\.venv\Lib\site-packages\django\core\handlers\base.py", line 197, in _get_response
    response = wrapped_callback(request, *callback_args, **callback_kwargs)
               ^^^^^^^^^^^^^^^^^^^^^^^^^^^^^^^^^^^^^^^^^^^^^^^^^^^^^^^^^^^^
  File "C:\django\.venv\Lib\site-packages\django\contrib\auth\decorators.py", line 23, in _wrapper_view
    return view_func(request, *args, **kwargs)
           ^^^^^^^^^^^^^^^^^^^^^^^^^^^^^^^^^^^
  File "C:\django\.venv\Lib\site-packages\django\contrib\auth\decorators.py", line 23, in _wrapper_view
    return view_func(request, *args, **kwargs)
           ^^^^^^^^^^^^^^^^^^^^^^^^^^^^^^^^^^^
  File "C:\django\insurance_company\insurance_company_app\views\accounts.py", line 47, in superuser_extra_view
    'clients_age': get_clients_age_statistics(),
                   ^^^^^^^^^^^^^^^^^^^^^^^^^^^^
  File "C:\django\insurance_company\insurance_company_app\views\statistics.py", line 43, in get_clients_age_statistics
    median_age = median(all_ages)
                 ^^^^^^^^^^^^^^^^
  File "C:\Program Files\WindowsApps\PythonSoftwareFoundation.Python.3.12_3.12.1008.0_x64__qbz5n2kfra8p0\Lib\statistics.py", line 617, in median
    raise StatisticsError("no median for empty data")
statistics.StatisticsError: no median for empty data
"GET /information/ HTTP/1.1" 500 84171
C:\django\insurance_company\insurance_company_app\views\statistics.py changed, reloading.
Watching for file changes with StatReloader
C:\django\insurance_company\insurance_company_app\models\insurance_client.py changed, reloading.
Watching for file changes with StatReloader
C:\django\insurance_company\insurance_company_app\models\insurance_client.py changed, reloading.
Watching for file changes with StatReloader
C:\django\insurance_company\insurance_company_app\models\insurance_client.py changed, reloading.
Watching for file changes with StatReloader
C:\django\insurance_company\insurance_company_app\views\statistics.py changed, reloading.
Watching for file changes with StatReloader
Internal Server Error: /information/
Traceback (most recent call last):
  File "C:\django\.venv\Lib\site-packages\django\core\handlers\exception.py", line 55, in inner
    response = get_response(request)
               ^^^^^^^^^^^^^^^^^^^^^
  File "C:\django\.venv\Lib\site-packages\django\core\handlers\base.py", line 197, in _get_response
    response = wrapped_callback(request, *callback_args, **callback_kwargs)
               ^^^^^^^^^^^^^^^^^^^^^^^^^^^^^^^^^^^^^^^^^^^^^^^^^^^^^^^^^^^^
  File "C:\django\.venv\Lib\site-packages\django\contrib\auth\decorators.py", line 23, in _wrapper_view
    return view_func(request, *args, **kwargs)
           ^^^^^^^^^^^^^^^^^^^^^^^^^^^^^^^^^^^
  File "C:\django\.venv\Lib\site-packages\django\contrib\auth\decorators.py", line 23, in _wrapper_view
    return view_func(request, *args, **kwargs)
           ^^^^^^^^^^^^^^^^^^^^^^^^^^^^^^^^^^^
  File "C:\django\insurance_company\insurance_company_app\views\accounts.py", line 48, in superuser_extra_view
    'agent_stats': get_agent_statistics()
                   ^^^^^^^^^^^^^^^^^^^^^^
  File "C:\django\insurance_company\insurance_company_app\views\statistics.py", line 60, in get_agent_statistics
    agent_stats = InsuranceAgent.objects.annotate(
                  ^^^^^^^^^^^^^^^^^^^^^^^^^^^^^^^^
  File "C:\django\.venv\Lib\site-packages\django\db\models\manager.py", line 87, in manager_method
    return getattr(self.get_queryset(), name)(*args, **kwargs)
           ^^^^^^^^^^^^^^^^^^^^^^^^^^^^^^^^^^^^^^^^^^^^^^^^^^^
  File "C:\django\.venv\Lib\site-packages\django\db\models\query.py", line 1630, in annotate
    return self._annotate(args, kwargs, select=True)
           ^^^^^^^^^^^^^^^^^^^^^^^^^^^^^^^^^^^^^^^^^
  File "C:\django\.venv\Lib\site-packages\django\db\models\query.py", line 1680, in _annotate
    clone.query.add_annotation(
  File "C:\django\.venv\Lib\site-packages\django\db\models\sql\query.py", line 1198, in add_annotation
    annotation = annotation.resolve_expression(self, allow_joins=True, reuse=None)
                 ^^^^^^^^^^^^^^^^^^^^^^^^^^^^^^^^^^^^^^^^^^^^^^^^^^^^^^^^^^^^^^^^^
  File "C:\django\.venv\Lib\site-packages\django\db\models\aggregates.py", line 65, in resolve_expression
    c = super().resolve_expression(query, allow_joins, reuse, summarize)
        ^^^^^^^^^^^^^^^^^^^^^^^^^^^^^^^^^^^^^^^^^^^^^^^^^^^^^^^^^^^^^^^^
  File "C:\django\.venv\Lib\site-packages\django\db\models\expressions.py", line 975, in resolve_expression
    c.source_expressions[pos] = arg.resolve_expression(
                                ^^^^^^^^^^^^^^^^^^^^^^^
  File "C:\django\.venv\Lib\site-packages\django\db\models\expressions.py", line 854, in resolve_expression
    return query.resolve_ref(self.name, allow_joins, reuse, summarize)
           ^^^^^^^^^^^^^^^^^^^^^^^^^^^^^^^^^^^^^^^^^^^^^^^^^^^^^^^^^^^
  File "C:\django\.venv\Lib\site-packages\django\db\models\sql\query.py", line 2014, in resolve_ref
    join_info = self.setup_joins(
                ^^^^^^^^^^^^^^^^^
  File "C:\django\.venv\Lib\site-packages\django\db\models\sql\query.py", line 1867, in setup_joins
    path, final_field, targets, rest = self.names_to_path(
                                       ^^^^^^^^^^^^^^^^^^^
  File "C:\django\.venv\Lib\site-packages\django\db\models\sql\query.py", line 1772, in names_to_path
    raise FieldError(
django.core.exceptions.FieldError: Cannot resolve keyword 'insurancecontract' into field. Choices are: address, age, basemodel_ptr, basemodel_ptr_id, branch_name, branch_name_id, created_at, id, name, phone_number, second_name, surname, updated_at
"GET /information/ HTTP/1.1" 500 130655
C:\django\insurance_company\insurance_company_app\views\accounts.py changed, reloading.
Watching for file changes with StatReloader
"GET /information/ HTTP/1.1" 200 647
"GET /information/ HTTP/1.1" 200 441
C:\django\insurance_company\insurance_company_app\middleware\current_datetime_info.py changed, reloading.
Watching for file changes with StatReloader
C:\django\insurance_company\insurance_company_app\middleware\current_datetime_info.py changed, reloading.
Watching for file changes with StatReloader
Internal Server Error: /home/
Traceback (most recent call last):
  File "C:\django\.venv\Lib\site-packages\django\core\handlers\exception.py", line 55, in inner
    response = get_response(request)
               ^^^^^^^^^^^^^^^^^^^^^
  File "C:\django\insurance_company\insurance_company_app\middleware\current_datetime_info.py", line 13, in __call__
    current_timezone = request.get_current_timezone_name()
                       ^^^^^^^^^^^^^^^^^^^^^^^^^^^^^^^^^
AttributeError: 'WSGIRequest' object has no attribute 'get_current_timezone_name'
"GET /home/ HTTP/1.1" 500 62982
C:\django\insurance_company\insurance_company_app\middleware\current_datetime_info.py changed, reloading.
Watching for file changes with StatReloader
Internal Server Error: /home/
Traceback (most recent call last):
  File "C:\django\.venv\Lib\site-packages\django\core\handlers\exception.py", line 55, in inner
    response = get_response(request)
               ^^^^^^^^^^^^^^^^^^^^^
  File "C:\django\insurance_company\insurance_company_app\middleware\current_datetime_info.py", line 13, in __call__
    current_timezone = request.get_current_timezone()
                       ^^^^^^^^^^^^^^^^^^^^^^^^^^^^
AttributeError: 'WSGIRequest' object has no attribute 'get_current_timezone'
"GET /home/ HTTP/1.1" 500 62942
C:\django\insurance_company\insurance_company_app\middleware\current_datetime_info.py changed, reloading.
Watching for file changes with StatReloader
"GET /home/ HTTP/1.1" 200 6822
C:\django\insurance_company\insurance_company_app\middleware\current_datetime_info.py changed, reloading.
Watching for file changes with StatReloader
Internal Server Error: /home/
Traceback (most recent call last):
  File "C:\django\.venv\Lib\site-packages\django\core\handlers\exception.py", line 55, in inner
    response = get_response(request)
               ^^^^^^^^^^^^^^^^^^^^^
  File "C:\django\insurance_company\insurance_company_app\middleware\current_datetime_info.py", line 13, in __call__
    current_timezone = request.user.profile.timezone
                       ^^^^^^^^^^^^^^^^^^^^
  File "C:\django\.venv\Lib\site-packages\django\utils\functional.py", line 253, in inner
    return func(_wrapped, *args)
           ^^^^^^^^^^^^^^^^^^^^^
AttributeError: 'User' object has no attribute 'profile'
"GET /home/ HTTP/1.1" 500 66741
C:\django\insurance_company\insurance_company_app\middleware\current_datetime_info.py changed, reloading.
Watching for file changes with StatReloader
Internal Server Error: /home/
Traceback (most recent call last):
  File "C:\django\.venv\Lib\site-packages\django\core\handlers\exception.py", line 55, in inner
    response = get_response(request)
               ^^^^^^^^^^^^^^^^^^^^^
  File "C:\django\insurance_company\insurance_company_app\middleware\current_datetime_info.py", line 13, in __call__
    current_timezone = request.user.timezone
                       ^^^^^^^^^^^^^^^^^^^^^
  File "C:\django\.venv\Lib\site-packages\django\utils\functional.py", line 253, in inner
    return func(_wrapped, *args)
           ^^^^^^^^^^^^^^^^^^^^^
AttributeError: 'User' object has no attribute 'timezone'
"GET /home/ HTTP/1.1" 500 66732
C:\django\insurance_company\insurance_company_app\middleware\current_datetime_info.py changed, reloading.
Watching for file changes with StatReloader
"GET /home/ HTTP/1.1" 200 6813
C:\django\insurance_company\insurance_company_app\middleware\current_datetime_info.py changed, reloading.
Watching for file changes with StatReloader
"GET /home/ HTTP/1.1" 200 6861
C:\django\insurance_company\insurance_company_app\middleware\current_datetime_info.py changed, reloading.
Watching for file changes with StatReloader
"GET /home/ HTTP/1.1" 200 6974
C:\django\insurance_company\insurance_company_app\middleware\current_datetime_info.py changed, reloading.
Watching for file changes with StatReloader
"GET /home/ HTTP/1.1" 200 6848
C:\django\insurance_company\insurance_company_app\middleware\current_datetime_info.py changed, reloading.
Watching for file changes with StatReloader
Internal Server Error: /home/
Traceback (most recent call last):
  File "C:\django\.venv\Lib\site-packages\django\core\handlers\exception.py", line 55, in inner
    response = get_response(request)
               ^^^^^^^^^^^^^^^^^^^^^
  File "C:\django\insurance_company\insurance_company_app\middleware\current_datetime_info.py", line 13, in __call__
    current_timezone = request.META['TZ']
                       ~~~~~~~~~~~~^^^^^^
KeyError: 'TZ'
"GET /home/ HTTP/1.1" 500 62606
Internal Server Error: /favicon.ico
Traceback (most recent call last):
  File "C:\django\.venv\Lib\site-packages\django\core\handlers\exception.py", line 55, in inner
    response = get_response(request)
               ^^^^^^^^^^^^^^^^^^^^^
  File "C:\django\insurance_company\insurance_company_app\middleware\current_datetime_info.py", line 13, in __call__
    current_timezone = request.META['TZ']
                       ~~~~~~~~~~~~^^^^^^
KeyError: 'TZ'
- Broken pipe from ('127.0.0.1', 50969)
C:\django\insurance_company\insurance_company_app\middleware\current_datetime_info.py changed, reloading.
Watching for file changes with StatReloader
C:\django\insurance_company\insurance_company_app\middleware\current_datetime_info.py changed, reloading.
Watching for file changes with StatReloader
"GET /home/ HTTP/1.1" 200 6849
C:\django\insurance_company\insurance_company_app\middleware\current_datetime_info.py changed, reloading.
Watching for file changes with StatReloader
"GET /home/ HTTP/1.1" 200 6916
C:\django\insurance_company\insurance_company_app\middleware\current_datetime_info.py changed, reloading.
Watching for file changes with StatReloader
"GET /home/ HTTP/1.1" 200 6874
C:\django\insurance_company\insurance_company_app\middleware\current_datetime_info.py changed, reloading.
Watching for file changes with StatReloader
C:\django\insurance_company\insurance_company_app\middleware\current_datetime_info.py changed, reloading.
Watching for file changes with StatReloader
"GET /home/ HTTP/1.1" 200 6814
C:\django\insurance_company\insurance_company_app\middleware\current_datetime_info.py changed, reloading.
Watching for file changes with StatReloader
Internal Server Error: /home/
Traceback (most recent call last):
  File "C:\django\.venv\Lib\site-packages\django\core\handlers\exception.py", line 55, in inner
    response = get_response(request)
               ^^^^^^^^^^^^^^^^^^^^^
  File "C:\django\insurance_company\insurance_company_app\middleware\current_datetime_info.py", line 13, in __call__
    current_timezone = request.COOKIES
                       ^^^^^^^^^^^^^^^^
AttributeError: 'WSGIRequest' object has no attribute 'COOCKIES'. Did you mean: 'COOKIES'?
"GET /home/ HTTP/1.1" 500 62840
Internal Server Error: /home/
Traceback (most recent call last):
  File "C:\django\.venv\Lib\site-packages\django\core\handlers\exception.py", line 55, in inner
    response = get_response(request)
               ^^^^^^^^^^^^^^^^^^^^^
  File "C:\django\insurance_company\insurance_company_app\middleware\current_datetime_info.py", line 13, in __call__
    current_timezone = request.COOKIES
                       ^^^^^^^^^^^^^^^^
AttributeError: 'WSGIRequest' object has no attribute 'COOCKIES'. Did you mean: 'COOKIES'?
"GET /home/ HTTP/1.1" 500 62840
C:\django\insurance_company\insurance_company_app\middleware\current_datetime_info.py changed, reloading.
Watching for file changes with StatReloader
Internal Server Error: /home/
Traceback (most recent call last):
  File "C:\django\.venv\Lib\site-packages\django\core\handlers\exception.py", line 55, in inner
    response = get_response(request)
               ^^^^^^^^^^^^^^^^^^^^^
  File "C:\django\insurance_company\insurance_company_app\middleware\current_datetime_info.py", line 13, in __call__
    current_timezone = request.COOCKIES
                       ^^^^^^^^^^^^^^^^
AttributeError: 'WSGIRequest' object has no attribute 'COOCKIES'. Did you mean: 'COOKIES'?
"GET /home/ HTTP/1.1" 500 62843
C:\django\insurance_company\insurance_company_app\middleware\current_datetime_info.py changed, reloading.
Watching for file changes with StatReloader
"GET /home/ HTTP/1.1" 200 7021
C:\django\insurance_company\insurance_company_app\middleware\current_datetime_info.py changed, reloading.
Watching for file changes with StatReloader
C:\django\insurance_company\insurance_company_app\middleware\current_datetime_info.py changed, reloading.
Watching for file changes with StatReloader
C:\django\insurance_company\insurance_company_app\middleware\current_datetime_info.py changed, reloading.
Watching for file changes with StatReloader
C:\django\insurance_company\insurance_company_app\models\insurance_agent.py changed, reloading.
Watching for file changes with StatReloader
C:\django\insurance_company\insurance_company_app\models\insurance_agent.py changed, reloading.
Watching for file changes with StatReloader
C:\django\insurance_company\insurance_company_app\models\insurance_client.py changed, reloading.
Watching for file changes with StatReloader
C:\django\insurance_company\insurance_company_app\models\insurance_client.py changed, reloading.
Watching for file changes with StatReloader
C:\django\insurance_company\insurance_company_app\models\insurance_client.py changed, reloading.
Watching for file changes with StatReloader
C:\django\insurance_company\insurance_company_app\models\insurance_client.py changed, reloading.
Watching for file changes with StatReloader
C:\django\insurance_company\insurance_company_app\models\insurance_client.py changed, reloading.
Watching for file changes with StatReloader
Watching for file changes with StatReloader
Internal Server Error: /admin/
Traceback (most recent call last):
  File "C:\django\.venv\Lib\site-packages\django\core\handlers\exception.py", line 55, in inner
    response = get_response(request)
               ^^^^^^^^^^^^^^^^^^^^^
  File "C:\django\insurance_company\insurance_company_app\middleware\current_datetime_info.py", line 19, in __call__
    request.current_timezone = current_timezone
                               ^^^^^^^^^^^^^^^^
NameError: name 'current_timezone' is not defined
"GET /admin/ HTTP/1.1" 500 63274
C:\django\insurance_company\insurance_company_app\middleware\current_datetime_info.py changed, reloading.
Watching for file changes with StatReloader
"GET /admin/ HTTP/1.1" 200 13190
"GET /static/admin/css/base.css HTTP/1.1" 304 0
"GET /static/admin/css/nav_sidebar.css HTTP/1.1" 304 0
"GET /static/admin/css/dashboard.css HTTP/1.1" 304 0
"GET /static/admin/css/dark_mode.css HTTP/1.1" 304 0
"GET /static/admin/js/nav_sidebar.js HTTP/1.1" 304 0
"GET /static/admin/css/responsive.css HTTP/1.1" 304 0
"GET /static/admin/js/theme.js HTTP/1.1" 304 0
"GET /static/admin/img/icon-changelink.svg HTTP/1.1" 200 380
"GET /static/admin/img/icon-addlink.svg HTTP/1.1" 200 331
"GET /admin/auth/user/ HTTP/1.1" 200 15376
"GET /static/admin/js/core.js HTTP/1.1" 304 0
"GET /static/admin/js/vendor/jquery/jquery.js HTTP/1.1" 304 0
"GET /static/admin/js/admin/RelatedObjectLookups.js HTTP/1.1" 304 0
"GET /static/admin/js/actions.js HTTP/1.1" 304 0
"GET /static/admin/js/urlify.js HTTP/1.1" 304 0
"GET /static/admin/js/prepopulate.js HTTP/1.1" 304 0
"GET /static/admin/css/changelists.css HTTP/1.1" 200 6811
"GET /static/admin/js/vendor/xregexp/xregexp.js HTTP/1.1" 304 0
"GET /static/admin/js/jquery.init.js HTTP/1.1" 200 347
"GET /static/admin/js/filters.js HTTP/1.1" 200 978
"GET /admin/jsi18n/ HTTP/1.1" 200 3342
"GET /static/admin/img/icon-no.svg HTTP/1.1" 200 560
"GET /static/admin/img/icon-yes.svg HTTP/1.1" 200 436
"GET /static/admin/img/search.svg HTTP/1.1" 200 458
"GET /static/admin/img/tooltag-add.svg HTTP/1.1" 200 331
"GET /static/admin/img/icon-viewlink.svg HTTP/1.1" 200 581
"GET /static/admin/img/sorting-icons.svg HTTP/1.1" 200 1097
Internal Server Error: /admin/auth/user/
Traceback (most recent call last):
  File "C:\django\.venv\Lib\site-packages\django\db\backends\utils.py", line 105, in _execute
    return self.cursor.execute(sql, params)
           ^^^^^^^^^^^^^^^^^^^^^^^^^^^^^^^^
  File "C:\django\.venv\Lib\site-packages\django\db\backends\sqlite3\base.py", line 329, in execute
    return super().execute(query, params)
           ^^^^^^^^^^^^^^^^^^^^^^^^^^^^^^
sqlite3.OperationalError: no such column: insurance_company_app_insuranceagent.user_id

The above exception was the direct cause of the following exception:

Traceback (most recent call last):
  File "C:\django\.venv\Lib\site-packages\django\core\handlers\exception.py", line 55, in inner
    response = get_response(request)
               ^^^^^^^^^^^^^^^^^^^^^
  File "C:\django\.venv\Lib\site-packages\django\core\handlers\base.py", line 197, in _get_response
    response = wrapped_callback(request, *callback_args, **callback_kwargs)
               ^^^^^^^^^^^^^^^^^^^^^^^^^^^^^^^^^^^^^^^^^^^^^^^^^^^^^^^^^^^^
  File "C:\django\.venv\Lib\site-packages\django\contrib\admin\options.py", line 716, in wrapper
    return self.admin_site.admin_view(view)(*args, **kwargs)
           ^^^^^^^^^^^^^^^^^^^^^^^^^^^^^^^^^^^^^^^^^^^^^^^^^
  File "C:\django\.venv\Lib\site-packages\django\utils\decorators.py", line 188, in _view_wrapper
    result = _process_exception(request, e)
             ^^^^^^^^^^^^^^^^^^^^^^^^^^^^^^
  File "C:\django\.venv\Lib\site-packages\django\utils\decorators.py", line 186, in _view_wrapper
    response = view_func(request, *args, **kwargs)
               ^^^^^^^^^^^^^^^^^^^^^^^^^^^^^^^^^^^
  File "C:\django\.venv\Lib\site-packages\django\views\decorators\cache.py", line 80, in _view_wrapper
    response = view_func(request, *args, **kwargs)
               ^^^^^^^^^^^^^^^^^^^^^^^^^^^^^^^^^^^
  File "C:\django\.venv\Lib\site-packages\django\contrib\admin\sites.py", line 240, in inner
    return view(request, *args, **kwargs)
           ^^^^^^^^^^^^^^^^^^^^^^^^^^^^^^
  File "C:\django\.venv\Lib\site-packages\django\utils\decorators.py", line 48, in _wrapper
    return bound_method(*args, **kwargs)
           ^^^^^^^^^^^^^^^^^^^^^^^^^^^^^
  File "C:\django\.venv\Lib\site-packages\django\utils\decorators.py", line 188, in _view_wrapper
    result = _process_exception(request, e)
             ^^^^^^^^^^^^^^^^^^^^^^^^^^^^^^
  File "C:\django\.venv\Lib\site-packages\django\utils\decorators.py", line 186, in _view_wrapper
    response = view_func(request, *args, **kwargs)
               ^^^^^^^^^^^^^^^^^^^^^^^^^^^^^^^^^^^
  File "C:\django\.venv\Lib\site-packages\django\contrib\admin\options.py", line 2018, in changelist_view
    response = self.response_action(
               ^^^^^^^^^^^^^^^^^^^^^
  File "C:\django\.venv\Lib\site-packages\django\contrib\admin\options.py", line 1650, in response_action
    response = func(self, request, queryset)
               ^^^^^^^^^^^^^^^^^^^^^^^^^^^^^
  File "C:\django\.venv\Lib\site-packages\django\contrib\admin\actions.py", line 39, in delete_selected
    ) = modeladmin.get_deleted_objects(queryset, request)
        ^^^^^^^^^^^^^^^^^^^^^^^^^^^^^^^^^^^^^^^^^^^^^^^^^
  File "C:\django\.venv\Lib\site-packages\django\contrib\admin\options.py", line 2160, in get_deleted_objects
    return get_deleted_objects(objs, request, self.admin_site)
           ^^^^^^^^^^^^^^^^^^^^^^^^^^^^^^^^^^^^^^^^^^^^^^^^^^^
  File "C:\django\.venv\Lib\site-packages\django\contrib\admin\utils.py", line 137, in get_deleted_objects
    collector.collect(objs)
  File "C:\django\.venv\Lib\site-packages\django\contrib\admin\utils.py", line 204, in collect
    return super().collect(objs, source_attr=source_attr, **kwargs)
           ^^^^^^^^^^^^^^^^^^^^^^^^^^^^^^^^^^^^^^^^^^^^^^^^^^^^^^^^
  File "C:\django\.venv\Lib\site-packages\django\db\models\deletion.py", line 348, in collect
    if getattr(on_delete, "lazy_sub_objs", False) or sub_objs:
                                                     ^^^^^^^^
  File "C:\django\.venv\Lib\site-packages\django\db\models\query.py", line 414, in __bool__
    self._fetch_all()
  File "C:\django\.venv\Lib\site-packages\django\db\models\query.py", line 1928, in _fetch_all
    self._result_cache = list(self._iterable_class(self))
                         ^^^^^^^^^^^^^^^^^^^^^^^^^^^^^^^^
  File "C:\django\.venv\Lib\site-packages\django\db\models\query.py", line 91, in __iter__
    results = compiler.execute_sql(
              ^^^^^^^^^^^^^^^^^^^^^
  File "C:\django\.venv\Lib\site-packages\django\db\models\sql\compiler.py", line 1562, in execute_sql
    cursor.execute(sql, params)
  File "C:\django\.venv\Lib\site-packages\django\db\backends\utils.py", line 122, in execute
    return super().execute(sql, params)
           ^^^^^^^^^^^^^^^^^^^^^^^^^^^^
  File "C:\django\.venv\Lib\site-packages\django\db\backends\utils.py", line 79, in execute
    return self._execute_with_wrappers(
           ^^^^^^^^^^^^^^^^^^^^^^^^^^^^
  File "C:\django\.venv\Lib\site-packages\django\db\backends\utils.py", line 92, in _execute_with_wrappers
    return executor(sql, params, many, context)
           ^^^^^^^^^^^^^^^^^^^^^^^^^^^^^^^^^^^^
  File "C:\django\.venv\Lib\site-packages\django\db\backends\utils.py", line 100, in _execute
    with self.db.wrap_database_errors:
  File "C:\django\.venv\Lib\site-packages\django\db\utils.py", line 91, in __exit__
    raise dj_exc_value.with_traceback(traceback) from exc_value
  File "C:\django\.venv\Lib\site-packages\django\db\backends\utils.py", line 105, in _execute
    return self.cursor.execute(sql, params)
           ^^^^^^^^^^^^^^^^^^^^^^^^^^^^^^^^
  File "C:\django\.venv\Lib\site-packages\django\db\backends\sqlite3\base.py", line 329, in execute
    return super().execute(query, params)
           ^^^^^^^^^^^^^^^^^^^^^^^^^^^^^^
django.db.utils.OperationalError: no such column: insurance_company_app_insuranceagent.user_id
"POST /admin/auth/user/ HTTP/1.1" 500 220089
"GET /admin/auth/user/ HTTP/1.1" 200 15376
"GET /admin/auth/user/ HTTP/1.1" 200 15376
"GET /admin/jsi18n/ HTTP/1.1" 200 3342
Internal Server Error: /admin/insurance_company_app/insuranceclient/
Traceback (most recent call last):
  File "C:\django\.venv\Lib\site-packages\django\db\backends\utils.py", line 105, in _execute
    return self.cursor.execute(sql, params)
           ^^^^^^^^^^^^^^^^^^^^^^^^^^^^^^^^
  File "C:\django\.venv\Lib\site-packages\django\db\backends\sqlite3\base.py", line 329, in execute
    return super().execute(query, params)
           ^^^^^^^^^^^^^^^^^^^^^^^^^^^^^^
sqlite3.OperationalError: no such column: insurance_company_app_insuranceclient.user_id

The above exception was the direct cause of the following exception:

Traceback (most recent call last):
  File "C:\django\.venv\Lib\site-packages\django\core\handlers\exception.py", line 55, in inner
    response = get_response(request)
               ^^^^^^^^^^^^^^^^^^^^^
  File "C:\django\.venv\Lib\site-packages\django\core\handlers\base.py", line 197, in _get_response
    response = wrapped_callback(request, *callback_args, **callback_kwargs)
               ^^^^^^^^^^^^^^^^^^^^^^^^^^^^^^^^^^^^^^^^^^^^^^^^^^^^^^^^^^^^
  File "C:\django\.venv\Lib\site-packages\django\contrib\admin\options.py", line 716, in wrapper
    return self.admin_site.admin_view(view)(*args, **kwargs)
           ^^^^^^^^^^^^^^^^^^^^^^^^^^^^^^^^^^^^^^^^^^^^^^^^^
  File "C:\django\.venv\Lib\site-packages\django\utils\decorators.py", line 188, in _view_wrapper
    result = _process_exception(request, e)
             ^^^^^^^^^^^^^^^^^^^^^^^^^^^^^^
  File "C:\django\.venv\Lib\site-packages\django\utils\decorators.py", line 186, in _view_wrapper
    response = view_func(request, *args, **kwargs)
               ^^^^^^^^^^^^^^^^^^^^^^^^^^^^^^^^^^^
  File "C:\django\.venv\Lib\site-packages\django\views\decorators\cache.py", line 80, in _view_wrapper
    response = view_func(request, *args, **kwargs)
               ^^^^^^^^^^^^^^^^^^^^^^^^^^^^^^^^^^^
  File "C:\django\.venv\Lib\site-packages\django\contrib\admin\sites.py", line 240, in inner
    return view(request, *args, **kwargs)
           ^^^^^^^^^^^^^^^^^^^^^^^^^^^^^^
  File "C:\django\.venv\Lib\site-packages\django\utils\decorators.py", line 48, in _wrapper
    return bound_method(*args, **kwargs)
           ^^^^^^^^^^^^^^^^^^^^^^^^^^^^^
  File "C:\django\.venv\Lib\site-packages\django\utils\decorators.py", line 188, in _view_wrapper
    result = _process_exception(request, e)
             ^^^^^^^^^^^^^^^^^^^^^^^^^^^^^^
  File "C:\django\.venv\Lib\site-packages\django\utils\decorators.py", line 186, in _view_wrapper
    response = view_func(request, *args, **kwargs)
               ^^^^^^^^^^^^^^^^^^^^^^^^^^^^^^^^^^^
  File "C:\django\.venv\Lib\site-packages\django\contrib\admin\options.py", line 2124, in changelist_view
    "selection_note": _("0 of %(cnt)s selected") % {"cnt": len(cl.result_list)},
                                                           ^^^^^^^^^^^^^^^^^^^
  File "C:\django\.venv\Lib\site-packages\django\db\models\query.py", line 382, in __len__
    self._fetch_all()
  File "C:\django\.venv\Lib\site-packages\django\db\models\query.py", line 1928, in _fetch_all
    self._result_cache = list(self._iterable_class(self))
                         ^^^^^^^^^^^^^^^^^^^^^^^^^^^^^^^^
  File "C:\django\.venv\Lib\site-packages\django\db\models\query.py", line 91, in __iter__
    results = compiler.execute_sql(
              ^^^^^^^^^^^^^^^^^^^^^
  File "C:\django\.venv\Lib\site-packages\django\db\models\sql\compiler.py", line 1562, in execute_sql
    cursor.execute(sql, params)
  File "C:\django\.venv\Lib\site-packages\django\db\backends\utils.py", line 122, in execute
    return super().execute(sql, params)
           ^^^^^^^^^^^^^^^^^^^^^^^^^^^^
  File "C:\django\.venv\Lib\site-packages\django\db\backends\utils.py", line 79, in execute
    return self._execute_with_wrappers(
           ^^^^^^^^^^^^^^^^^^^^^^^^^^^^
  File "C:\django\.venv\Lib\site-packages\django\db\backends\utils.py", line 92, in _execute_with_wrappers
    return executor(sql, params, many, context)
           ^^^^^^^^^^^^^^^^^^^^^^^^^^^^^^^^^^^^
  File "C:\django\.venv\Lib\site-packages\django\db\backends\utils.py", line 100, in _execute
    with self.db.wrap_database_errors:
  File "C:\django\.venv\Lib\site-packages\django\db\utils.py", line 91, in __exit__
    raise dj_exc_value.with_traceback(traceback) from exc_value
  File "C:\django\.venv\Lib\site-packages\django\db\backends\utils.py", line 105, in _execute
    return self.cursor.execute(sql, params)
           ^^^^^^^^^^^^^^^^^^^^^^^^^^^^^^^^
  File "C:\django\.venv\Lib\site-packages\django\db\backends\sqlite3\base.py", line 329, in execute
    return super().execute(query, params)
           ^^^^^^^^^^^^^^^^^^^^^^^^^^^^^^
django.db.utils.OperationalError: no such column: insurance_company_app_insuranceclient.user_id
"GET /admin/insurance_company_app/insuranceclient/ HTTP/1.1" 500 181697
"GET /admin/auth/user/ HTTP/1.1" 200 15376
Internal Server Error: /admin/insurance_company_app/insuranceclient/
Traceback (most recent call last):
  File "C:\django\.venv\Lib\site-packages\django\db\backends\utils.py", line 105, in _execute
    return self.cursor.execute(sql, params)
           ^^^^^^^^^^^^^^^^^^^^^^^^^^^^^^^^
  File "C:\django\.venv\Lib\site-packages\django\db\backends\sqlite3\base.py", line 329, in execute
    return super().execute(query, params)
           ^^^^^^^^^^^^^^^^^^^^^^^^^^^^^^
sqlite3.OperationalError: no such column: insurance_company_app_insuranceclient.user_id

The above exception was the direct cause of the following exception:

Traceback (most recent call last):
  File "C:\django\.venv\Lib\site-packages\django\core\handlers\exception.py", line 55, in inner
    response = get_response(request)
               ^^^^^^^^^^^^^^^^^^^^^
  File "C:\django\.venv\Lib\site-packages\django\core\handlers\base.py", line 197, in _get_response
    response = wrapped_callback(request, *callback_args, **callback_kwargs)
               ^^^^^^^^^^^^^^^^^^^^^^^^^^^^^^^^^^^^^^^^^^^^^^^^^^^^^^^^^^^^
  File "C:\django\.venv\Lib\site-packages\django\contrib\admin\options.py", line 716, in wrapper
    return self.admin_site.admin_view(view)(*args, **kwargs)
           ^^^^^^^^^^^^^^^^^^^^^^^^^^^^^^^^^^^^^^^^^^^^^^^^^
  File "C:\django\.venv\Lib\site-packages\django\utils\decorators.py", line 188, in _view_wrapper
    result = _process_exception(request, e)
             ^^^^^^^^^^^^^^^^^^^^^^^^^^^^^^
  File "C:\django\.venv\Lib\site-packages\django\utils\decorators.py", line 186, in _view_wrapper
    response = view_func(request, *args, **kwargs)
               ^^^^^^^^^^^^^^^^^^^^^^^^^^^^^^^^^^^
  File "C:\django\.venv\Lib\site-packages\django\views\decorators\cache.py", line 80, in _view_wrapper
    response = view_func(request, *args, **kwargs)
               ^^^^^^^^^^^^^^^^^^^^^^^^^^^^^^^^^^^
  File "C:\django\.venv\Lib\site-packages\django\contrib\admin\sites.py", line 240, in inner
    return view(request, *args, **kwargs)
           ^^^^^^^^^^^^^^^^^^^^^^^^^^^^^^
  File "C:\django\.venv\Lib\site-packages\django\utils\decorators.py", line 48, in _wrapper
    return bound_method(*args, **kwargs)
           ^^^^^^^^^^^^^^^^^^^^^^^^^^^^^
  File "C:\django\.venv\Lib\site-packages\django\utils\decorators.py", line 188, in _view_wrapper
    result = _process_exception(request, e)
             ^^^^^^^^^^^^^^^^^^^^^^^^^^^^^^
  File "C:\django\.venv\Lib\site-packages\django\utils\decorators.py", line 186, in _view_wrapper
    response = view_func(request, *args, **kwargs)
               ^^^^^^^^^^^^^^^^^^^^^^^^^^^^^^^^^^^
  File "C:\django\.venv\Lib\site-packages\django\contrib\admin\options.py", line 2124, in changelist_view
    "selection_note": _("0 of %(cnt)s selected") % {"cnt": len(cl.result_list)},
                                                           ^^^^^^^^^^^^^^^^^^^
  File "C:\django\.venv\Lib\site-packages\django\db\models\query.py", line 382, in __len__
    self._fetch_all()
  File "C:\django\.venv\Lib\site-packages\django\db\models\query.py", line 1928, in _fetch_all
    self._result_cache = list(self._iterable_class(self))
                         ^^^^^^^^^^^^^^^^^^^^^^^^^^^^^^^^
  File "C:\django\.venv\Lib\site-packages\django\db\models\query.py", line 91, in __iter__
    results = compiler.execute_sql(
              ^^^^^^^^^^^^^^^^^^^^^
  File "C:\django\.venv\Lib\site-packages\django\db\models\sql\compiler.py", line 1562, in execute_sql
    cursor.execute(sql, params)
  File "C:\django\.venv\Lib\site-packages\django\db\backends\utils.py", line 122, in execute
    return super().execute(sql, params)
           ^^^^^^^^^^^^^^^^^^^^^^^^^^^^
  File "C:\django\.venv\Lib\site-packages\django\db\backends\utils.py", line 79, in execute
    return self._execute_with_wrappers(
           ^^^^^^^^^^^^^^^^^^^^^^^^^^^^
  File "C:\django\.venv\Lib\site-packages\django\db\backends\utils.py", line 92, in _execute_with_wrappers
    return executor(sql, params, many, context)
           ^^^^^^^^^^^^^^^^^^^^^^^^^^^^^^^^^^^^
  File "C:\django\.venv\Lib\site-packages\django\db\backends\utils.py", line 100, in _execute
    with self.db.wrap_database_errors:
  File "C:\django\.venv\Lib\site-packages\django\db\utils.py", line 91, in __exit__
    raise dj_exc_value.with_traceback(traceback) from exc_value
  File "C:\django\.venv\Lib\site-packages\django\db\backends\utils.py", line 105, in _execute
    return self.cursor.execute(sql, params)
           ^^^^^^^^^^^^^^^^^^^^^^^^^^^^^^^^
  File "C:\django\.venv\Lib\site-packages\django\db\backends\sqlite3\base.py", line 329, in execute
    return super().execute(query, params)
           ^^^^^^^^^^^^^^^^^^^^^^^^^^^^^^
django.db.utils.OperationalError: no such column: insurance_company_app_insuranceclient.user_id
"GET /admin/insurance_company_app/insuranceclient/ HTTP/1.1" 500 181697
C:\django\insurance_company\insurance_company_app\models\insurance_client.py changed, reloading.
Watching for file changes with StatReloader
"GET /admin/insurance_company_app/insuranceclient/ HTTP/1.1" 200 9964
"GET /admin/jsi18n/ HTTP/1.1" 200 3342
C:\django\insurance_company\insurance_company_app\models\insurance_client.py changed, reloading.
Watching for file changes with StatReloader
Watching for file changes with StatReloader
"GET /admin/insurance_company_app/insuranceclient/ HTTP/1.1" 200 9964
"GET /admin/jsi18n/ HTTP/1.1" 200 3342
- Broken pipe from ('127.0.0.1', 52177)
"GET /admin/auth/user/ HTTP/1.1" 200 15376
"GET /admin/jsi18n/ HTTP/1.1" 200 3342
"GET /admin/auth/user/6/change/ HTTP/1.1" 200 26182
"GET /admin/jsi18n/ HTTP/1.1" 200 3342
"GET /static/admin/css/forms.css HTTP/1.1" 304 0
"GET /static/admin/js/calendar.js HTTP/1.1" 304 0
"GET /static/admin/js/admin/DateTimeShortcuts.js HTTP/1.1" 304 0
"GET /static/admin/js/prepopulate_init.js HTTP/1.1" 200 586
"GET /static/admin/js/change_form.js HTTP/1.1" 200 606
"GET /static/admin/js/SelectBox.js HTTP/1.1" 200 4530
"GET /static/admin/js/SelectFilter2.js HTTP/1.1" 200 15492
"GET /static/admin/css/widgets.css HTTP/1.1" 200 11800
"GET /static/admin/img/icon-unknown.svg HTTP/1.1" 200 655
"GET /static/admin/img/icon-unknown-alt.svg HTTP/1.1" 200 655
"GET /static/admin/img/icon-clock.svg HTTP/1.1" 200 677
"GET /static/admin/img/selector-icons.svg HTTP/1.1" 200 3291
"GET /static/admin/img/icon-calendar.svg HTTP/1.1" 200 1086
"GET /admin/insurance_company_app/insuranceclient/ HTTP/1.1" 200 9964
"GET /admin/jsi18n/ HTTP/1.1" 200 3342
"GET /admin/insurance_company_app/insuranceclient/add/ HTTP/1.1" 200 16153
"GET /admin/jsi18n/ HTTP/1.1" 200 3342
Internal Server Error: /admin/insurance_company_app/insuranceclient/add/
Traceback (most recent call last):
  File "C:\django\.venv\Lib\site-packages\django\core\handlers\exception.py", line 55, in inner
    response = get_response(request)
               ^^^^^^^^^^^^^^^^^^^^^
  File "C:\django\.venv\Lib\site-packages\django\core\handlers\base.py", line 197, in _get_response
    response = wrapped_callback(request, *callback_args, **callback_kwargs)
               ^^^^^^^^^^^^^^^^^^^^^^^^^^^^^^^^^^^^^^^^^^^^^^^^^^^^^^^^^^^^
  File "C:\django\.venv\Lib\site-packages\django\contrib\admin\options.py", line 716, in wrapper
    return self.admin_site.admin_view(view)(*args, **kwargs)
           ^^^^^^^^^^^^^^^^^^^^^^^^^^^^^^^^^^^^^^^^^^^^^^^^^
  File "C:\django\.venv\Lib\site-packages\django\utils\decorators.py", line 188, in _view_wrapper
    result = _process_exception(request, e)
             ^^^^^^^^^^^^^^^^^^^^^^^^^^^^^^
  File "C:\django\.venv\Lib\site-packages\django\utils\decorators.py", line 186, in _view_wrapper
    response = view_func(request, *args, **kwargs)
               ^^^^^^^^^^^^^^^^^^^^^^^^^^^^^^^^^^^
  File "C:\django\.venv\Lib\site-packages\django\views\decorators\cache.py", line 80, in _view_wrapper
    response = view_func(request, *args, **kwargs)
               ^^^^^^^^^^^^^^^^^^^^^^^^^^^^^^^^^^^
  File "C:\django\.venv\Lib\site-packages\django\contrib\admin\sites.py", line 240, in inner
    return view(request, *args, **kwargs)
           ^^^^^^^^^^^^^^^^^^^^^^^^^^^^^^
  File "C:\django\.venv\Lib\site-packages\django\contrib\admin\options.py", line 1945, in add_view
    return self.changeform_view(request, None, form_url, extra_context)
           ^^^^^^^^^^^^^^^^^^^^^^^^^^^^^^^^^^^^^^^^^^^^^^^^^^^^^^^^^^^^
  File "C:\django\.venv\Lib\site-packages\django\utils\decorators.py", line 48, in _wrapper
    return bound_method(*args, **kwargs)
           ^^^^^^^^^^^^^^^^^^^^^^^^^^^^^
  File "C:\django\.venv\Lib\site-packages\django\utils\decorators.py", line 188, in _view_wrapper
    result = _process_exception(request, e)
             ^^^^^^^^^^^^^^^^^^^^^^^^^^^^^^
  File "C:\django\.venv\Lib\site-packages\django\utils\decorators.py", line 186, in _view_wrapper
    response = view_func(request, *args, **kwargs)
               ^^^^^^^^^^^^^^^^^^^^^^^^^^^^^^^^^^^
  File "C:\django\.venv\Lib\site-packages\django\contrib\admin\options.py", line 1804, in changeform_view
    return self._changeform_view(request, object_id, form_url, extra_context)
           ^^^^^^^^^^^^^^^^^^^^^^^^^^^^^^^^^^^^^^^^^^^^^^^^^^^^^^^^^^^^^^^^^^
  File "C:\django\.venv\Lib\site-packages\django\contrib\admin\options.py", line 1849, in _changeform_view
    form_validated = form.is_valid()
                     ^^^^^^^^^^^^^^^
  File "C:\django\.venv\Lib\site-packages\django\forms\forms.py", line 197, in is_valid
    return self.is_bound and not self.errors
                                 ^^^^^^^^^^^
  File "C:\django\.venv\Lib\site-packages\django\forms\forms.py", line 192, in errors
    self.full_clean()
  File "C:\django\.venv\Lib\site-packages\django\forms\forms.py", line 329, in full_clean
    self._post_clean()
  File "C:\django\.venv\Lib\site-packages\django\forms\models.py", line 496, in _post_clean
    self.instance.full_clean(exclude=exclude, validate_unique=False)
  File "C:\django\.venv\Lib\site-packages\django\db\models\base.py", line 1527, in full_clean
    self.clean()
  File "C:\django\insurance_company\insurance_company_app\models\insurance_client.py", line 28, in clean
    raise ValueError('Phone number must be in the format +375 (29) XXX-XX-XX')
ValueError: Phone number must be in the format +375 (29) XXX-XX-XX
"POST /admin/insurance_company_app/insuranceclient/add/ HTTP/1.1" 500 145180
"GET /admin/insurance_company_app/insuranceclient/add/ HTTP/1.1" 200 16153
"POST /admin/insurance_company_app/insuranceclient/add/ HTTP/1.1" 302 0
"GET /admin/insurance_company_app/insuranceclient/add/ HTTP/1.1" 200 16434
"GET /admin/jsi18n/ HTTP/1.1" 200 3342
Internal Server Error: /admin/insurance_company_app/insuranceclient/
Traceback (most recent call last):
  File "C:\django\.venv\Lib\site-packages\django\db\models\options.py", line 681, in get_field
    return self.fields_map[field_name]
           ~~~~~~~~~~~~~~~^^^^^^^^^^^^
KeyError: 'get_description'

During handling of the above exception, another exception occurred:

Traceback (most recent call last):
  File "C:\django\.venv\Lib\site-packages\django\contrib\admin\utils.py", line 289, in lookup_field
    f = _get_non_gfk_field(opts, name)
        ^^^^^^^^^^^^^^^^^^^^^^^^^^^^^^
  File "C:\django\.venv\Lib\site-packages\django\contrib\admin\utils.py", line 322, in _get_non_gfk_field
    field = opts.get_field(name)
            ^^^^^^^^^^^^^^^^^^^^
  File "C:\django\.venv\Lib\site-packages\django\db\models\options.py", line 683, in get_field
    raise FieldDoesNotExist(
django.core.exceptions.FieldDoesNotExist: InsuranceClient has no field named 'get_description'

During handling of the above exception, another exception occurred:

Traceback (most recent call last):
  File "C:\django\.venv\Lib\site-packages\django\core\handlers\exception.py", line 55, in inner
    response = get_response(request)
               ^^^^^^^^^^^^^^^^^^^^^
  File "C:\django\.venv\Lib\site-packages\django\core\handlers\base.py", line 220, in _get_response
    response = response.render()
               ^^^^^^^^^^^^^^^^^
  File "C:\django\.venv\Lib\site-packages\django\template\response.py", line 114, in render
    self.content = self.rendered_content
                   ^^^^^^^^^^^^^^^^^^^^^
  File "C:\django\.venv\Lib\site-packages\django\template\response.py", line 92, in rendered_content
    return template.render(context, self._request)
           ^^^^^^^^^^^^^^^^^^^^^^^^^^^^^^^^^^^^^^^
  File "C:\django\.venv\Lib\site-packages\django\template\backends\django.py", line 61, in render
    return self.template.render(context)
           ^^^^^^^^^^^^^^^^^^^^^^^^^^^^^
  File "C:\django\.venv\Lib\site-packages\django\template\base.py", line 171, in render
    return self._render(context)
           ^^^^^^^^^^^^^^^^^^^^^
  File "C:\django\.venv\Lib\site-packages\django\template\base.py", line 163, in _render
    return self.nodelist.render(context)
           ^^^^^^^^^^^^^^^^^^^^^^^^^^^^^
  File "C:\django\.venv\Lib\site-packages\django\template\base.py", line 1000, in render
    return SafeString("".join([node.render_annotated(context) for node in self]))
                               ^^^^^^^^^^^^^^^^^^^^^^^^^^^^^^
  File "C:\django\.venv\Lib\site-packages\django\template\base.py", line 961, in render_annotated
    return self.render(context)
           ^^^^^^^^^^^^^^^^^^^^
  File "C:\django\.venv\Lib\site-packages\django\template\loader_tags.py", line 159, in render
    return compiled_parent._render(context)
           ^^^^^^^^^^^^^^^^^^^^^^^^^^^^^^^^
  File "C:\django\.venv\Lib\site-packages\django\template\base.py", line 163, in _render
    return self.nodelist.render(context)
           ^^^^^^^^^^^^^^^^^^^^^^^^^^^^^
  File "C:\django\.venv\Lib\site-packages\django\template\base.py", line 1000, in render
    return SafeString("".join([node.render_annotated(context) for node in self]))
                               ^^^^^^^^^^^^^^^^^^^^^^^^^^^^^^
  File "C:\django\.venv\Lib\site-packages\django\template\base.py", line 961, in render_annotated
    return self.render(context)
           ^^^^^^^^^^^^^^^^^^^^
  File "C:\django\.venv\Lib\site-packages\django\template\loader_tags.py", line 159, in render
    return compiled_parent._render(context)
           ^^^^^^^^^^^^^^^^^^^^^^^^^^^^^^^^
  File "C:\django\.venv\Lib\site-packages\django\template\base.py", line 163, in _render
    return self.nodelist.render(context)
           ^^^^^^^^^^^^^^^^^^^^^^^^^^^^^
  File "C:\django\.venv\Lib\site-packages\django\template\base.py", line 1000, in render
    return SafeString("".join([node.render_annotated(context) for node in self]))
                               ^^^^^^^^^^^^^^^^^^^^^^^^^^^^^^
  File "C:\django\.venv\Lib\site-packages\django\template\base.py", line 961, in render_annotated
    return self.render(context)
           ^^^^^^^^^^^^^^^^^^^^
  File "C:\django\.venv\Lib\site-packages\django\template\loader_tags.py", line 65, in render
    result = block.nodelist.render(context)
             ^^^^^^^^^^^^^^^^^^^^^^^^^^^^^^
  File "C:\django\.venv\Lib\site-packages\django\template\base.py", line 1000, in render
    return SafeString("".join([node.render_annotated(context) for node in self]))
                               ^^^^^^^^^^^^^^^^^^^^^^^^^^^^^^
  File "C:\django\.venv\Lib\site-packages\django\template\base.py", line 961, in render_annotated
    return self.render(context)
           ^^^^^^^^^^^^^^^^^^^^
  File "C:\django\.venv\Lib\site-packages\django\template\loader_tags.py", line 65, in render
    result = block.nodelist.render(context)
             ^^^^^^^^^^^^^^^^^^^^^^^^^^^^^^
  File "C:\django\.venv\Lib\site-packages\django\template\base.py", line 1000, in render
    return SafeString("".join([node.render_annotated(context) for node in self]))
                               ^^^^^^^^^^^^^^^^^^^^^^^^^^^^^^
  File "C:\django\.venv\Lib\site-packages\django\template\base.py", line 961, in render_annotated
    return self.render(context)
           ^^^^^^^^^^^^^^^^^^^^
  File "C:\django\.venv\Lib\site-packages\django\contrib\admin\templatetags\base.py", line 45, in render
    return super().render(context)
           ^^^^^^^^^^^^^^^^^^^^^^^
  File "C:\django\.venv\Lib\site-packages\django\template\library.py", line 258, in render
    _dict = self.func(*resolved_args, **resolved_kwargs)
            ^^^^^^^^^^^^^^^^^^^^^^^^^^^^^^^^^^^^^^^^^^^^
  File "C:\django\.venv\Lib\site-packages\django\contrib\admin\templatetags\admin_list.py", line 345, in result_list
    "results": list(results(cl)),
               ^^^^^^^^^^^^^^^^^
  File "C:\django\.venv\Lib\site-packages\django\contrib\admin\templatetags\admin_list.py", line 321, in results
    yield ResultList(None, items_for_result(cl, res, None))
          ^^^^^^^^^^^^^^^^^^^^^^^^^^^^^^^^^^^^^^^^^^^^^^^^^
  File "C:\django\.venv\Lib\site-packages\django\contrib\admin\templatetags\admin_list.py", line 312, in __init__
    super().__init__(*items)
  File "C:\django\.venv\Lib\site-packages\django\contrib\admin\templatetags\admin_list.py", line 217, in items_for_result
    f, attr, value = lookup_field(field_name, result, cl.model_admin)
                     ^^^^^^^^^^^^^^^^^^^^^^^^^^^^^^^^^^^^^^^^^^^^^^^^
  File "C:\django\.venv\Lib\site-packages\django\contrib\admin\utils.py", line 298, in lookup_field
    value = attr(obj)
            ^^^^^^^^^
  File "C:\django\insurance_company\insurance_company_app\admin.py", line 45, in get_description
    return obj.description
           ^^^^^^^^^^^^^^^
AttributeError: 'InsuranceClient' object has no attribute 'description'
"GET /admin/insurance_company_app/insuranceclient/ HTTP/1.1" 500 378115
"GET /admin/insurance_company_app/insuranceclient/add/ HTTP/1.1" 200 16153
Internal Server Error: /admin/insurance_company_app/insuranceclient/
Traceback (most recent call last):
  File "C:\django\.venv\Lib\site-packages\django\db\models\options.py", line 681, in get_field
    return self.fields_map[field_name]
           ~~~~~~~~~~~~~~~^^^^^^^^^^^^
KeyError: 'get_description'

During handling of the above exception, another exception occurred:

Traceback (most recent call last):
  File "C:\django\.venv\Lib\site-packages\django\contrib\admin\utils.py", line 289, in lookup_field
    f = _get_non_gfk_field(opts, name)
        ^^^^^^^^^^^^^^^^^^^^^^^^^^^^^^
  File "C:\django\.venv\Lib\site-packages\django\contrib\admin\utils.py", line 322, in _get_non_gfk_field
    field = opts.get_field(name)
            ^^^^^^^^^^^^^^^^^^^^
  File "C:\django\.venv\Lib\site-packages\django\db\models\options.py", line 683, in get_field
    raise FieldDoesNotExist(
django.core.exceptions.FieldDoesNotExist: InsuranceClient has no field named 'get_description'

During handling of the above exception, another exception occurred:

Traceback (most recent call last):
  File "C:\django\.venv\Lib\site-packages\django\core\handlers\exception.py", line 55, in inner
    response = get_response(request)
               ^^^^^^^^^^^^^^^^^^^^^
  File "C:\django\.venv\Lib\site-packages\django\core\handlers\base.py", line 220, in _get_response
    response = response.render()
               ^^^^^^^^^^^^^^^^^
  File "C:\django\.venv\Lib\site-packages\django\template\response.py", line 114, in render
    self.content = self.rendered_content
                   ^^^^^^^^^^^^^^^^^^^^^
  File "C:\django\.venv\Lib\site-packages\django\template\response.py", line 92, in rendered_content
    return template.render(context, self._request)
           ^^^^^^^^^^^^^^^^^^^^^^^^^^^^^^^^^^^^^^^
  File "C:\django\.venv\Lib\site-packages\django\template\backends\django.py", line 61, in render
    return self.template.render(context)
           ^^^^^^^^^^^^^^^^^^^^^^^^^^^^^
  File "C:\django\.venv\Lib\site-packages\django\template\base.py", line 171, in render
    return self._render(context)
           ^^^^^^^^^^^^^^^^^^^^^
  File "C:\django\.venv\Lib\site-packages\django\template\base.py", line 163, in _render
    return self.nodelist.render(context)
           ^^^^^^^^^^^^^^^^^^^^^^^^^^^^^
  File "C:\django\.venv\Lib\site-packages\django\template\base.py", line 1000, in render
    return SafeString("".join([node.render_annotated(context) for node in self]))
                               ^^^^^^^^^^^^^^^^^^^^^^^^^^^^^^
  File "C:\django\.venv\Lib\site-packages\django\template\base.py", line 961, in render_annotated
    return self.render(context)
           ^^^^^^^^^^^^^^^^^^^^
  File "C:\django\.venv\Lib\site-packages\django\template\loader_tags.py", line 159, in render
    return compiled_parent._render(context)
           ^^^^^^^^^^^^^^^^^^^^^^^^^^^^^^^^
  File "C:\django\.venv\Lib\site-packages\django\template\base.py", line 163, in _render
    return self.nodelist.render(context)
           ^^^^^^^^^^^^^^^^^^^^^^^^^^^^^
  File "C:\django\.venv\Lib\site-packages\django\template\base.py", line 1000, in render
    return SafeString("".join([node.render_annotated(context) for node in self]))
                               ^^^^^^^^^^^^^^^^^^^^^^^^^^^^^^
  File "C:\django\.venv\Lib\site-packages\django\template\base.py", line 961, in render_annotated
    return self.render(context)
           ^^^^^^^^^^^^^^^^^^^^
  File "C:\django\.venv\Lib\site-packages\django\template\loader_tags.py", line 159, in render
    return compiled_parent._render(context)
           ^^^^^^^^^^^^^^^^^^^^^^^^^^^^^^^^
  File "C:\django\.venv\Lib\site-packages\django\template\base.py", line 163, in _render
    return self.nodelist.render(context)
           ^^^^^^^^^^^^^^^^^^^^^^^^^^^^^
  File "C:\django\.venv\Lib\site-packages\django\template\base.py", line 1000, in render
    return SafeString("".join([node.render_annotated(context) for node in self]))
                               ^^^^^^^^^^^^^^^^^^^^^^^^^^^^^^
  File "C:\django\.venv\Lib\site-packages\django\template\base.py", line 961, in render_annotated
    return self.render(context)
           ^^^^^^^^^^^^^^^^^^^^
  File "C:\django\.venv\Lib\site-packages\django\template\loader_tags.py", line 65, in render
    result = block.nodelist.render(context)
             ^^^^^^^^^^^^^^^^^^^^^^^^^^^^^^
  File "C:\django\.venv\Lib\site-packages\django\template\base.py", line 1000, in render
    return SafeString("".join([node.render_annotated(context) for node in self]))
                               ^^^^^^^^^^^^^^^^^^^^^^^^^^^^^^
  File "C:\django\.venv\Lib\site-packages\django\template\base.py", line 961, in render_annotated
    return self.render(context)
           ^^^^^^^^^^^^^^^^^^^^
  File "C:\django\.venv\Lib\site-packages\django\template\loader_tags.py", line 65, in render
    result = block.nodelist.render(context)
             ^^^^^^^^^^^^^^^^^^^^^^^^^^^^^^
  File "C:\django\.venv\Lib\site-packages\django\template\base.py", line 1000, in render
    return SafeString("".join([node.render_annotated(context) for node in self]))
                               ^^^^^^^^^^^^^^^^^^^^^^^^^^^^^^
  File "C:\django\.venv\Lib\site-packages\django\template\base.py", line 961, in render_annotated
    return self.render(context)
           ^^^^^^^^^^^^^^^^^^^^
  File "C:\django\.venv\Lib\site-packages\django\contrib\admin\templatetags\base.py", line 45, in render
    return super().render(context)
           ^^^^^^^^^^^^^^^^^^^^^^^
  File "C:\django\.venv\Lib\site-packages\django\template\library.py", line 258, in render
    _dict = self.func(*resolved_args, **resolved_kwargs)
            ^^^^^^^^^^^^^^^^^^^^^^^^^^^^^^^^^^^^^^^^^^^^
  File "C:\django\.venv\Lib\site-packages\django\contrib\admin\templatetags\admin_list.py", line 345, in result_list
    "results": list(results(cl)),
               ^^^^^^^^^^^^^^^^^
  File "C:\django\.venv\Lib\site-packages\django\contrib\admin\templatetags\admin_list.py", line 321, in results
    yield ResultList(None, items_for_result(cl, res, None))
          ^^^^^^^^^^^^^^^^^^^^^^^^^^^^^^^^^^^^^^^^^^^^^^^^^
  File "C:\django\.venv\Lib\site-packages\django\contrib\admin\templatetags\admin_list.py", line 312, in __init__
    super().__init__(*items)
  File "C:\django\.venv\Lib\site-packages\django\contrib\admin\templatetags\admin_list.py", line 217, in items_for_result
    f, attr, value = lookup_field(field_name, result, cl.model_admin)
                     ^^^^^^^^^^^^^^^^^^^^^^^^^^^^^^^^^^^^^^^^^^^^^^^^
  File "C:\django\.venv\Lib\site-packages\django\contrib\admin\utils.py", line 298, in lookup_field
    value = attr(obj)
            ^^^^^^^^^
  File "C:\django\insurance_company\insurance_company_app\admin.py", line 45, in get_description
    return obj.description
           ^^^^^^^^^^^^^^^
AttributeError: 'InsuranceClient' object has no attribute 'description'
"GET /admin/insurance_company_app/insuranceclient/ HTTP/1.1" 500 378115
C:\django\insurance_company\insurance_company_app\admin.py changed, reloading.
Watching for file changes with StatReloader
"GET /admin/insurance_company_app/insuranceclient/ HTTP/1.1" 200 12789
"GET /admin/jsi18n/ HTTP/1.1" 200 3342
C:\django\insurance_company\insurance_company_app\models\insurance_client.py changed, reloading.
Watching for file changes with StatReloader
Watching for file changes with StatReloader
"GET /admin/insurance_company_app/insuranceclient/ HTTP/1.1" 200 13990
"GET /admin/jsi18n/ HTTP/1.1" 200 3342
C:\django\insurance_company\insurance_company_app\admin.py changed, reloading.
Watching for file changes with StatReloader
C:\django\insurance_company\insurance_company_app\admin.py changed, reloading.
Watching for file changes with StatReloader
"GET /admin/insurance_company_app/insuranceclient/ HTTP/1.1" 200 14105
"GET /admin/jsi18n/ HTTP/1.1" 200 3342
C:\django\insurance_company\insurance_company_app\admin.py changed, reloading.
Watching for file changes with StatReloader
C:\django\insurance_company\insurance_company_app\admin.py changed, reloading.
Watching for file changes with StatReloader
C:\django\insurance_company\insurance_company_app\admin.py changed, reloading.
Watching for file changes with StatReloader
"GET /admin/insurance_company_app/insuranceclient/ HTTP/1.1" 200 14105
"GET /admin/jsi18n/ HTTP/1.1" 200 3342
C:\django\insurance_company\insurance_company_app\admin.py changed, reloading.
Watching for file changes with StatReloader
"GET /admin/auth/user/ HTTP/1.1" 200 15376
"GET /admin/jsi18n/ HTTP/1.1" 200 3342
"GET /admin/auth/user/2/change/ HTTP/1.1" 200 26100
"GET /admin/jsi18n/ HTTP/1.1" 200 3342
C:\django\insurance_company\insurance_company_app\middleware\current_datetime_info.py changed, reloading.
Watching for file changes with StatReloader
C:\django\insurance_company\insurance_company_app\models\insurance_agent.py changed, reloading.
Watching for file changes with StatReloader
Watching for file changes with StatReloader
Watching for file changes with StatReloader
Internal Server Error: /branches/
Traceback (most recent call last):
  File "C:\django\.venv\Lib\site-packages\django\core\handlers\exception.py", line 55, in inner
    response = get_response(request)
               ^^^^^^^^^^^^^^^^^^^^^
  File "C:\django\insurance_company\insurance_company_app\middleware\current_datetime_info.py", line 15, in __call__
    current_timezone = datetime.now(timezone.utc).astimezone().tzinfo
                       ^^^^^^^^^^^^
AttributeError: module 'datetime' has no attribute 'now'
"GET /branches/ HTTP/1.1" 500 62907
Internal Server Error: /favicon.ico
Traceback (most recent call last):
  File "C:\django\.venv\Lib\site-packages\django\core\handlers\exception.py", line 55, in inner
    response = get_response(request)
               ^^^^^^^^^^^^^^^^^^^^^
  File "C:\django\insurance_company\insurance_company_app\middleware\current_datetime_info.py", line 15, in __call__
    current_timezone = datetime.now(timezone.utc).astimezone().tzinfo
                       ^^^^^^^^^^^^
AttributeError: module 'datetime' has no attribute 'now'
- Broken pipe from ('127.0.0.1', 53160)
C:\django\insurance_company\insurance_company_app\middleware\current_datetime_info.py changed, reloading.
Watching for file changes with StatReloader
Internal Server Error: /branches/
Traceback (most recent call last):
  File "C:\django\.venv\Lib\site-packages\django\core\handlers\exception.py", line 55, in inner
    response = get_response(request)
               ^^^^^^^^^^^^^^^^^^^^^
  File "C:\django\insurance_company\insurance_company_app\middleware\current_datetime_info.py", line 15, in __call__
    current_timezone = datetime.datetime.now(timezone.utc).astimezone().tzinfo
                                             ^^^^^^^^^^^^
AttributeError: module 'django.utils.timezone' has no attribute 'utc'
"GET /branches/ HTTP/1.1" 500 63020
Internal Server Error: /favicon.ico
Traceback (most recent call last):
  File "C:\django\.venv\Lib\site-packages\django\core\handlers\exception.py", line 55, in inner
    response = get_response(request)
               ^^^^^^^^^^^^^^^^^^^^^
  File "C:\django\insurance_company\insurance_company_app\middleware\current_datetime_info.py", line 15, in __call__
    current_timezone = datetime.datetime.now(timezone.utc).astimezone().tzinfo
                                             ^^^^^^^^^^^^
AttributeError: module 'django.utils.timezone' has no attribute 'utc'
- Broken pipe from ('127.0.0.1', 53180)
C:\django\insurance_company\insurance_company_app\middleware\current_datetime_info.py changed, reloading.
Watching for file changes with StatReloader
"GET /branches/ HTTP/1.1" 200 7379
Not Found: /favicon.ico
- Broken pipe from ('127.0.0.1', 53187)
C:\django\insurance_company\insurance_company_app\views\company_branches.py changed, reloading.
Watching for file changes with StatReloader
C:\django\insurance_company\insurance_company_app\views\company_branches.py changed, reloading.
Watching for file changes with StatReloader
C:\django\insurance_company\insurance_company_app\models\insurance_agent.py changed, reloading.
Watching for file changes with StatReloader
C:\django\insurance_company\insurance_company\settings.py changed, reloading.
Watching for file changes with StatReloader
C:\django\insurance_company\insurance_company\settings.py changed, reloading.
Watching for file changes with StatReloader
C:\django\insurance_company\insurance_company\settings.py changed, reloading.
Watching for file changes with StatReloader
"GET /branches/ HTTP/1.1" 200 7379
Not Found: /favicon.ico
- Broken pipe from ('127.0.0.1', 55629)
C:\django\insurance_company\insurance_company\settings.py changed, reloading.
Watching for file changes with StatReloader
C:\django\insurance_company\insurance_company\settings.py changed, reloading.
